2011-10-25 23:39:20 [4521] [INFO] Starting gunicorn 0.13.4
2011-10-25 23:39:20 [4521] [INFO] Listening at: unix:/home/mpatlas/projects/django_testgeo/testgeo/deploy/gunicorn.sock (4521)
2011-10-25 23:39:20 [4521] [INFO] Using worker: gevent
2011-10-25 23:39:20 [4528] [INFO] Booting worker with pid: 4528
2011-10-25 23:39:20 [4529] [INFO] Booting worker with pid: 4529
2011-10-25 23:39:20 [4528] [INFO] Made Psycopg Green
2011-10-25 23:39:20 [4529] [INFO] Made Psycopg Green
/home/mpatlas/projects/django_testgeo/testgeo/deploy/run_gunicorn.sh: line 4: /var/www/.bashrc: No such file or directory
2011-10-25 23:40:17 [4591] [INFO] Starting gunicorn 0.13.4
2011-10-25 23:40:17 [4591] [ERROR] Retrying in 1 second.
2011-10-25 23:40:18 [4591] [ERROR] Retrying in 1 second.
2011-10-25 23:40:19 [4591] [ERROR] Retrying in 1 second.
2011-10-25 23:40:20 [4591] [ERROR] Retrying in 1 second.
2011-10-25 23:40:21 [4591] [ERROR] Retrying in 1 second.
2011-10-25 23:40:22 [4591] [ERROR] Can't connect to /home/mpatlas/projects/django_testgeo/testgeo/deploy/gunicorn.sock
/home/mpatlas/projects/django_testgeo/testgeo/deploy/run_gunicorn.sh: line 4: /var/www/.bashrc: No such file or directory
2011-10-25 23:40:23 [4598] [INFO] Starting gunicorn 0.13.4
2011-10-25 23:40:23 [4598] [ERROR] Retrying in 1 second.
/home/mpatlas/projects/django_testgeo/testgeo/deploy/run_gunicorn.sh: line 4: /var/www/.bashrc: No such file or directory
2011-10-25 23:40:33 [4606] [INFO] Starting gunicorn 0.13.4
2011-10-25 23:40:33 [4606] [ERROR] Retrying in 1 second.
2011-10-25 23:40:34 [4606] [ERROR] Retrying in 1 second.
2011-10-25 23:40:35 [4606] [ERROR] Retrying in 1 second.
2011-10-25 23:40:36 [4606] [ERROR] Retrying in 1 second.
2011-10-25 23:40:37 [4606] [ERROR] Retrying in 1 second.
2011-10-25 23:40:38 [4606] [ERROR] Can't connect to /home/mpatlas/projects/django_testgeo/testgeo/deploy/gunicorn.sock
/home/mpatlas/projects/django_testgeo/testgeo/deploy/run_gunicorn.sh: line 4: /var/www/.bashrc: No such file or directory
2011-10-25 23:40:39 [4613] [INFO] Starting gunicorn 0.13.4
2011-10-25 23:40:39 [4613] [ERROR] Retrying in 1 second.
2011-10-25 23:40:40 [4613] [ERROR] Retrying in 1 second.
2011-10-25 23:40:41 [4613] [ERROR] Retrying in 1 second.
2011-10-25 23:40:42 [4613] [ERROR] Retrying in 1 second.
2011-10-25 23:40:43 [4613] [ERROR] Retrying in 1 second.
2011-10-25 23:40:44 [4613] [ERROR] Can't connect to /home/mpatlas/projects/django_testgeo/testgeo/deploy/gunicorn.sock
/home/mpatlas/projects/django_testgeo/testgeo/deploy/run_gunicorn.sh: line 4: /var/www/.bashrc: No such file or directory
2011-10-25 23:40:45 [4622] [INFO] Starting gunicorn 0.13.4
2011-10-25 23:40:45 [4622] [ERROR] Retrying in 1 second.
2011-10-25 23:40:46 [4622] [ERROR] Retrying in 1 second.
2011-10-25 23:40:47 [4622] [ERROR] Retrying in 1 second.
2011-10-25 23:40:48 [4622] [ERROR] Retrying in 1 second.
2011-10-25 23:41:35 [4635] [INFO] Starting gunicorn 0.13.4
2011-10-25 23:41:35 [4635] [INFO] Listening at: unix:/home/mpatlas/projects/django_testgeo/testgeo/deploy/gunicorn.sock (4635)
2011-10-25 23:41:35 [4635] [INFO] Using worker: gevent
2011-10-25 23:41:35 [4642] [INFO] Booting worker with pid: 4642
2011-10-25 23:41:35 [4643] [INFO] Booting worker with pid: 4643
2011-10-25 23:41:35 [4643] [INFO] Made Psycopg Green
2011-10-25 23:41:35 [4642] [INFO] Made Psycopg Green
2011-10-26 18:07:38 [816] [INFO] Starting gunicorn 0.13.4
2011-10-26 18:07:38 [816] [INFO] Listening at: unix:/home/mpatlas/projects/django_testgeo/testgeo/deploy/gunicorn.sock (816)
2011-10-26 18:07:38 [816] [INFO] Using worker: gevent
2011-10-26 18:07:38 [824] [INFO] Booting worker with pid: 824
2011-10-26 18:07:38 [825] [INFO] Booting worker with pid: 825
2011-10-26 18:07:38 [825] [INFO] Made Psycopg Green
2011-10-26 18:07:38 [824] [INFO] Made Psycopg Green
2011-10-26 18:09:36 [803] [INFO] Starting gunicorn 0.13.4
2011-10-26 18:09:36 [803] [INFO] Listening at: unix:/home/mpatlas/projects/django_testgeo/testgeo/deploy/gunicorn.sock (803)
2011-10-26 18:09:36 [803] [INFO] Using worker: gevent
2011-10-26 18:09:36 [822] [INFO] Booting worker with pid: 822
2011-10-26 18:09:36 [823] [INFO] Booting worker with pid: 823
2011-10-26 18:09:36 [823] [INFO] Made Psycopg Green
2011-10-26 18:09:36 [822] [INFO] Made Psycopg Green
2011-10-31 23:11:20 [12233] [INFO] Starting gunicorn 0.13.4
2011-10-31 23:11:20 [12233] [INFO] Listening at: unix:/home/mpatlas/projects/django_testgeo/testgeo/deploy/gunicorn.sock (12233)
2011-10-31 23:11:20 [12233] [INFO] Using worker: gevent
2011-10-31 23:11:20 [12240] [INFO] Booting worker with pid: 12240
2011-10-31 23:11:20 [12241] [INFO] Booting worker with pid: 12241
2011-10-31 23:11:20 [12240] [INFO] Made Psycopg Green
2011-10-31 23:11:20 [12241] [INFO] Made Psycopg Green
2011-10-31 16:11:22 [12240] [ERROR] Exception in worker process:
Traceback (most recent call last):
  File "/home/mpatlas/virtualenvs/mpatlas_dev/lib/python2.7/site-packages/gunicorn/arbiter.py", line 456, in spawn_worker
    worker.init_process()
  File "/home/mpatlas/virtualenvs/mpatlas_dev/lib/python2.7/site-packages/gunicorn/workers/ggevent.py", line 99, in init_process
    super(GeventWorker, self).init_process()
  File "/home/mpatlas/virtualenvs/mpatlas_dev/lib/python2.7/site-packages/gunicorn/workers/base.py", line 100, in init_process
    self.wsgi = self.app.wsgi()
  File "/home/mpatlas/virtualenvs/mpatlas_dev/lib/python2.7/site-packages/gunicorn/app/base.py", line 101, in wsgi
    self.callable = self.load()
  File "/home/mpatlas/virtualenvs/mpatlas_dev/lib/python2.7/site-packages/gunicorn/app/djangoapp.py", line 128, in load
    self.validate()
  File "/home/mpatlas/virtualenvs/mpatlas_dev/lib/python2.7/site-packages/gunicorn/app/djangoapp.py", line 116, in validate
    if get_validation_errors(s):
  File "/home/mpatlas/virtualenvs/mpatlas_dev/lib/python2.7/site-packages/django/core/management/validation.py", line 28, in get_validation_errors
    from django.db import models, connection
  File "/home/mpatlas/virtualenvs/mpatlas_dev/lib/python2.7/site-packages/django/db/__init__.py", line 78, in <module>
    connection = connections[DEFAULT_DB_ALIAS]
  File "/home/mpatlas/virtualenvs/mpatlas_dev/lib/python2.7/site-packages/django/db/utils.py", line 94, in __getitem__
    conn = backend.DatabaseWrapper(db, alias)
  File "/home/mpatlas/virtualenvs/mpatlas_dev/lib/python2.7/site-packages/django/contrib/gis/db/backends/postgis/base.py", line 11, in __init__
    self.ops = PostGISOperations(self)
  File "/home/mpatlas/virtualenvs/mpatlas_dev/lib/python2.7/site-packages/django/contrib/gis/db/backends/postgis/operations.py", line 91, in __init__
    vtup = self.postgis_version_tuple()
  File "/home/mpatlas/virtualenvs/mpatlas_dev/lib/python2.7/site-packages/django/contrib/gis/db/backends/postgis/operations.py", line 445, in postgis_version_tuple
    version = self.postgis_lib_version()
  File "/home/mpatlas/virtualenvs/mpatlas_dev/lib/python2.7/site-packages/django/contrib/gis/db/backends/postgis/operations.py", line 425, in postgis_lib_version
    return self._get_postgis_func('postgis_lib_version')
  File "/home/mpatlas/virtualenvs/mpatlas_dev/lib/python2.7/site-packages/django/contrib/gis/db/backends/postgis/operations.py", line 406, in _get_postgis_func
    cursor = self.connection._cursor()
  File "/home/mpatlas/virtualenvs/mpatlas_dev/lib/python2.7/site-packages/django/db/backends/postgresql_psycopg2/base.py", line 140, in _cursor
    self.connection = Database.connect(**conn_params)
  File "/home/mpatlas/projects/django_testgeo/testgeo/deploy/psyco_gevent.py", line 44, in gevent_wait_callback
    state = conn.poll()
OperationalError: asynchronous connection failed
2011-10-31 16:11:22 [12240] [INFO] Worker exiting (pid: 12240)
2011-10-31 16:11:22 [12241] [ERROR] Exception in worker process:
Traceback (most recent call last):
  File "/home/mpatlas/virtualenvs/mpatlas_dev/lib/python2.7/site-packages/gunicorn/arbiter.py", line 456, in spawn_worker
    worker.init_process()
  File "/home/mpatlas/virtualenvs/mpatlas_dev/lib/python2.7/site-packages/gunicorn/workers/ggevent.py", line 99, in init_process
    super(GeventWorker, self).init_process()
  File "/home/mpatlas/virtualenvs/mpatlas_dev/lib/python2.7/site-packages/gunicorn/workers/base.py", line 100, in init_process
    self.wsgi = self.app.wsgi()
  File "/home/mpatlas/virtualenvs/mpatlas_dev/lib/python2.7/site-packages/gunicorn/app/base.py", line 101, in wsgi
    self.callable = self.load()
  File "/home/mpatlas/virtualenvs/mpatlas_dev/lib/python2.7/site-packages/gunicorn/app/djangoapp.py", line 128, in load
    self.validate()
  File "/home/mpatlas/virtualenvs/mpatlas_dev/lib/python2.7/site-packages/gunicorn/app/djangoapp.py", line 116, in validate
    if get_validation_errors(s):
  File "/home/mpatlas/virtualenvs/mpatlas_dev/lib/python2.7/site-packages/django/core/management/validation.py", line 28, in get_validation_errors
    from django.db import models, connection
  File "/home/mpatlas/virtualenvs/mpatlas_dev/lib/python2.7/site-packages/django/db/__init__.py", line 78, in <module>
    connection = connections[DEFAULT_DB_ALIAS]
  File "/home/mpatlas/virtualenvs/mpatlas_dev/lib/python2.7/site-packages/django/db/utils.py", line 94, in __getitem__
    conn = backend.DatabaseWrapper(db, alias)
  File "/home/mpatlas/virtualenvs/mpatlas_dev/lib/python2.7/site-packages/django/contrib/gis/db/backends/postgis/base.py", line 11, in __init__
    self.ops = PostGISOperations(self)
  File "/home/mpatlas/virtualenvs/mpatlas_dev/lib/python2.7/site-packages/django/contrib/gis/db/backends/postgis/operations.py", line 91, in __init__
    vtup = self.postgis_version_tuple()
  File "/home/mpatlas/virtualenvs/mpatlas_dev/lib/python2.7/site-packages/django/contrib/gis/db/backends/postgis/operations.py", line 445, in postgis_version_tuple
    version = self.postgis_lib_version()
  File "/home/mpatlas/virtualenvs/mpatlas_dev/lib/python2.7/site-packages/django/contrib/gis/db/backends/postgis/operations.py", line 425, in postgis_lib_version
    return self._get_postgis_func('postgis_lib_version')
  File "/home/mpatlas/virtualenvs/mpatlas_dev/lib/python2.7/site-packages/django/contrib/gis/db/backends/postgis/operations.py", line 406, in _get_postgis_func
    cursor = self.connection._cursor()
  File "/home/mpatlas/virtualenvs/mpatlas_dev/lib/python2.7/site-packages/django/db/backends/postgresql_psycopg2/base.py", line 140, in _cursor
    self.connection = Database.connect(**conn_params)
  File "/home/mpatlas/projects/django_testgeo/testgeo/deploy/psyco_gevent.py", line 44, in gevent_wait_callback
    state = conn.poll()
OperationalError: asynchronous connection failed
2011-10-31 16:11:22 [12241] [INFO] Worker exiting (pid: 12241)
2011-10-31 23:11:23 [12233] [INFO] Shutting down: Master
2011-10-31 23:11:23 [12233] [INFO] Reason: Worker failed to boot.
2011-10-31 23:11:24 [12290] [INFO] Starting gunicorn 0.13.4
2011-10-31 23:11:24 [12290] [INFO] Listening at: unix:/home/mpatlas/projects/django_testgeo/testgeo/deploy/gunicorn.sock (12290)
2011-10-31 23:11:24 [12290] [INFO] Using worker: gevent
2011-10-31 23:11:24 [12297] [INFO] Booting worker with pid: 12297
2011-10-31 23:11:24 [12298] [INFO] Booting worker with pid: 12298
2011-10-31 23:11:24 [12297] [INFO] Made Psycopg Green
2011-10-31 23:11:24 [12298] [INFO] Made Psycopg Green
2011-10-31 16:11:24 [12297] [ERROR] Exception in worker process:
Traceback (most recent call last):
  File "/home/mpatlas/virtualenvs/mpatlas_dev/lib/python2.7/site-packages/gunicorn/arbiter.py", line 456, in spawn_worker
    worker.init_process()
  File "/home/mpatlas/virtualenvs/mpatlas_dev/lib/python2.7/site-packages/gunicorn/workers/ggevent.py", line 99, in init_process
    super(GeventWorker, self).init_process()
  File "/home/mpatlas/virtualenvs/mpatlas_dev/lib/python2.7/site-packages/gunicorn/workers/base.py", line 100, in init_process
    self.wsgi = self.app.wsgi()
  File "/home/mpatlas/virtualenvs/mpatlas_dev/lib/python2.7/site-packages/gunicorn/app/base.py", line 101, in wsgi
    self.callable = self.load()
  File "/home/mpatlas/virtualenvs/mpatlas_dev/lib/python2.7/site-packages/gunicorn/app/djangoapp.py", line 128, in load
    self.validate()
  File "/home/mpatlas/virtualenvs/mpatlas_dev/lib/python2.7/site-packages/gunicorn/app/djangoapp.py", line 116, in validate
    if get_validation_errors(s):
  File "/home/mpatlas/virtualenvs/mpatlas_dev/lib/python2.7/site-packages/django/core/management/validation.py", line 28, in get_validation_errors
    from django.db import models, connection
  File "/home/mpatlas/virtualenvs/mpatlas_dev/lib/python2.7/site-packages/django/db/__init__.py", line 78, in <module>
    connection = connections[DEFAULT_DB_ALIAS]
  File "/home/mpatlas/virtualenvs/mpatlas_dev/lib/python2.7/site-packages/django/db/utils.py", line 94, in __getitem__
    conn = backend.DatabaseWrapper(db, alias)
  File "/home/mpatlas/virtualenvs/mpatlas_dev/lib/python2.7/site-packages/django/contrib/gis/db/backends/postgis/base.py", line 11, in __init__
    self.ops = PostGISOperations(self)
  File "/home/mpatlas/virtualenvs/mpatlas_dev/lib/python2.7/site-packages/django/contrib/gis/db/backends/postgis/operations.py", line 91, in __init__
    vtup = self.postgis_version_tuple()
  File "/home/mpatlas/virtualenvs/mpatlas_dev/lib/python2.7/site-packages/django/contrib/gis/db/backends/postgis/operations.py", line 445, in postgis_version_tuple
    version = self.postgis_lib_version()
  File "/home/mpatlas/virtualenvs/mpatlas_dev/lib/python2.7/site-packages/django/contrib/gis/db/backends/postgis/operations.py", line 425, in postgis_lib_version
    return self._get_postgis_func('postgis_lib_version')
  File "/home/mpatlas/virtualenvs/mpatlas_dev/lib/python2.7/site-packages/django/contrib/gis/db/backends/postgis/operations.py", line 406, in _get_postgis_func
    cursor = self.connection._cursor()
  File "/home/mpatlas/virtualenvs/mpatlas_dev/lib/python2.7/site-packages/django/db/backends/postgresql_psycopg2/base.py", line 140, in _cursor
    self.connection = Database.connect(**conn_params)
  File "/home/mpatlas/projects/django_testgeo/testgeo/deploy/psyco_gevent.py", line 44, in gevent_wait_callback
    state = conn.poll()
OperationalError: asynchronous connection failed
2011-10-31 16:11:24 [12297] [INFO] Worker exiting (pid: 12297)
2011-10-31 16:11:24 [12298] [ERROR] Exception in worker process:
Traceback (most recent call last):
  File "/home/mpatlas/virtualenvs/mpatlas_dev/lib/python2.7/site-packages/gunicorn/arbiter.py", line 456, in spawn_worker
    worker.init_process()
  File "/home/mpatlas/virtualenvs/mpatlas_dev/lib/python2.7/site-packages/gunicorn/workers/ggevent.py", line 99, in init_process
    super(GeventWorker, self).init_process()
  File "/home/mpatlas/virtualenvs/mpatlas_dev/lib/python2.7/site-packages/gunicorn/workers/base.py", line 100, in init_process
    self.wsgi = self.app.wsgi()
  File "/home/mpatlas/virtualenvs/mpatlas_dev/lib/python2.7/site-packages/gunicorn/app/base.py", line 101, in wsgi
    self.callable = self.load()
  File "/home/mpatlas/virtualenvs/mpatlas_dev/lib/python2.7/site-packages/gunicorn/app/djangoapp.py", line 128, in load
    self.validate()
  File "/home/mpatlas/virtualenvs/mpatlas_dev/lib/python2.7/site-packages/gunicorn/app/djangoapp.py", line 116, in validate
    if get_validation_errors(s):
  File "/home/mpatlas/virtualenvs/mpatlas_dev/lib/python2.7/site-packages/django/core/management/validation.py", line 28, in get_validation_errors
    from django.db import models, connection
  File "/home/mpatlas/virtualenvs/mpatlas_dev/lib/python2.7/site-packages/django/db/__init__.py", line 78, in <module>
    connection = connections[DEFAULT_DB_ALIAS]
  File "/home/mpatlas/virtualenvs/mpatlas_dev/lib/python2.7/site-packages/django/db/utils.py", line 94, in __getitem__
    conn = backend.DatabaseWrapper(db, alias)
  File "/home/mpatlas/virtualenvs/mpatlas_dev/lib/python2.7/site-packages/django/contrib/gis/db/backends/postgis/base.py", line 11, in __init__
    self.ops = PostGISOperations(self)
  File "/home/mpatlas/virtualenvs/mpatlas_dev/lib/python2.7/site-packages/django/contrib/gis/db/backends/postgis/operations.py", line 91, in __init__
    vtup = self.postgis_version_tuple()
  File "/home/mpatlas/virtualenvs/mpatlas_dev/lib/python2.7/site-packages/django/contrib/gis/db/backends/postgis/operations.py", line 445, in postgis_version_tuple
    version = self.postgis_lib_version()
  File "/home/mpatlas/virtualenvs/mpatlas_dev/lib/python2.7/site-packages/django/contrib/gis/db/backends/postgis/operations.py", line 425, in postgis_lib_version
    return self._get_postgis_func('postgis_lib_version')
  File "/home/mpatlas/virtualenvs/mpatlas_dev/lib/python2.7/site-packages/django/contrib/gis/db/backends/postgis/operations.py", line 406, in _get_postgis_func
    cursor = self.connection._cursor()
  File "/home/mpatlas/virtualenvs/mpatlas_dev/lib/python2.7/site-packages/django/db/backends/postgresql_psycopg2/base.py", line 140, in _cursor
    self.connection = Database.connect(**conn_params)
  File "/home/mpatlas/projects/django_testgeo/testgeo/deploy/psyco_gevent.py", line 44, in gevent_wait_callback
    state = conn.poll()
OperationalError: asynchronous connection failed
2011-10-31 16:11:24 [12298] [INFO] Worker exiting (pid: 12298)
2011-10-31 23:11:25 [12290] [INFO] Shutting down: Master
2011-10-31 23:11:25 [12290] [INFO] Reason: Worker failed to boot.
2011-10-31 23:11:26 [12345] [INFO] Starting gunicorn 0.13.4
2011-10-31 23:11:26 [12345] [INFO] Listening at: unix:/home/mpatlas/projects/django_testgeo/testgeo/deploy/gunicorn.sock (12345)
2011-10-31 23:11:26 [12345] [INFO] Using worker: gevent
2011-10-31 23:11:26 [12352] [INFO] Booting worker with pid: 12352
2011-10-31 23:11:26 [12353] [INFO] Booting worker with pid: 12353
2011-10-31 23:11:26 [12352] [INFO] Made Psycopg Green
2011-10-31 23:11:26 [12353] [INFO] Made Psycopg Green
2011-10-31 16:11:27 [12353] [ERROR] Exception in worker process:
Traceback (most recent call last):
  File "/home/mpatlas/virtualenvs/mpatlas_dev/lib/python2.7/site-packages/gunicorn/arbiter.py", line 456, in spawn_worker
    worker.init_process()
  File "/home/mpatlas/virtualenvs/mpatlas_dev/lib/python2.7/site-packages/gunicorn/workers/ggevent.py", line 99, in init_process
    super(GeventWorker, self).init_process()
  File "/home/mpatlas/virtualenvs/mpatlas_dev/lib/python2.7/site-packages/gunicorn/workers/base.py", line 100, in init_process
    self.wsgi = self.app.wsgi()
  File "/home/mpatlas/virtualenvs/mpatlas_dev/lib/python2.7/site-packages/gunicorn/app/base.py", line 101, in wsgi
    self.callable = self.load()
  File "/home/mpatlas/virtualenvs/mpatlas_dev/lib/python2.7/site-packages/gunicorn/app/djangoapp.py", line 128, in load
    self.validate()
  File "/home/mpatlas/virtualenvs/mpatlas_dev/lib/python2.7/site-packages/gunicorn/app/djangoapp.py", line 116, in validate
    if get_validation_errors(s):
  File "/home/mpatlas/virtualenvs/mpatlas_dev/lib/python2.7/site-packages/django/core/management/validation.py", line 28, in get_validation_errors
    from django.db import models, connection
  File "/home/mpatlas/virtualenvs/mpatlas_dev/lib/python2.7/site-packages/django/db/__init__.py", line 78, in <module>
    connection = connections[DEFAULT_DB_ALIAS]
  File "/home/mpatlas/virtualenvs/mpatlas_dev/lib/python2.7/site-packages/django/db/utils.py", line 94, in __getitem__
    conn = backend.DatabaseWrapper(db, alias)
  File "/home/mpatlas/virtualenvs/mpatlas_dev/lib/python2.7/site-packages/django/contrib/gis/db/backends/postgis/base.py", line 11, in __init__
    self.ops = PostGISOperations(self)
  File "/home/mpatlas/virtualenvs/mpatlas_dev/lib/python2.7/site-packages/django/contrib/gis/db/backends/postgis/operations.py", line 91, in __init__
    vtup = self.postgis_version_tuple()
  File "/home/mpatlas/virtualenvs/mpatlas_dev/lib/python2.7/site-packages/django/contrib/gis/db/backends/postgis/operations.py", line 445, in postgis_version_tuple
    version = self.postgis_lib_version()
  File "/home/mpatlas/virtualenvs/mpatlas_dev/lib/python2.7/site-packages/django/contrib/gis/db/backends/postgis/operations.py", line 425, in postgis_lib_version
    return self._get_postgis_func('postgis_lib_version')
  File "/home/mpatlas/virtualenvs/mpatlas_dev/lib/python2.7/site-packages/django/contrib/gis/db/backends/postgis/operations.py", line 406, in _get_postgis_func
    cursor = self.connection._cursor()
  File "/home/mpatlas/virtualenvs/mpatlas_dev/lib/python2.7/site-packages/django/db/backends/postgresql_psycopg2/base.py", line 140, in _cursor
    self.connection = Database.connect(**conn_params)
  File "/home/mpatlas/projects/django_testgeo/testgeo/deploy/psyco_gevent.py", line 44, in gevent_wait_callback
    state = conn.poll()
OperationalError: asynchronous connection failed
2011-10-31 16:11:27 [12353] [INFO] Worker exiting (pid: 12353)
2011-10-31 16:11:27 [12352] [ERROR] Exception in worker process:
Traceback (most recent call last):
  File "/home/mpatlas/virtualenvs/mpatlas_dev/lib/python2.7/site-packages/gunicorn/arbiter.py", line 456, in spawn_worker
    worker.init_process()
  File "/home/mpatlas/virtualenvs/mpatlas_dev/lib/python2.7/site-packages/gunicorn/workers/ggevent.py", line 99, in init_process
    super(GeventWorker, self).init_process()
  File "/home/mpatlas/virtualenvs/mpatlas_dev/lib/python2.7/site-packages/gunicorn/workers/base.py", line 100, in init_process
    self.wsgi = self.app.wsgi()
  File "/home/mpatlas/virtualenvs/mpatlas_dev/lib/python2.7/site-packages/gunicorn/app/base.py", line 101, in wsgi
    self.callable = self.load()
  File "/home/mpatlas/virtualenvs/mpatlas_dev/lib/python2.7/site-packages/gunicorn/app/djangoapp.py", line 128, in load
    self.validate()
  File "/home/mpatlas/virtualenvs/mpatlas_dev/lib/python2.7/site-packages/gunicorn/app/djangoapp.py", line 116, in validate
    if get_validation_errors(s):
  File "/home/mpatlas/virtualenvs/mpatlas_dev/lib/python2.7/site-packages/django/core/management/validation.py", line 28, in get_validation_errors
    from django.db import models, connection
  File "/home/mpatlas/virtualenvs/mpatlas_dev/lib/python2.7/site-packages/django/db/__init__.py", line 78, in <module>
    connection = connections[DEFAULT_DB_ALIAS]
  File "/home/mpatlas/virtualenvs/mpatlas_dev/lib/python2.7/site-packages/django/db/utils.py", line 94, in __getitem__
    conn = backend.DatabaseWrapper(db, alias)
  File "/home/mpatlas/virtualenvs/mpatlas_dev/lib/python2.7/site-packages/django/contrib/gis/db/backends/postgis/base.py", line 11, in __init__
    self.ops = PostGISOperations(self)
  File "/home/mpatlas/virtualenvs/mpatlas_dev/lib/python2.7/site-packages/django/contrib/gis/db/backends/postgis/operations.py", line 91, in __init__
    vtup = self.postgis_version_tuple()
  File "/home/mpatlas/virtualenvs/mpatlas_dev/lib/python2.7/site-packages/django/contrib/gis/db/backends/postgis/operations.py", line 445, in postgis_version_tuple
    version = self.postgis_lib_version()
  File "/home/mpatlas/virtualenvs/mpatlas_dev/lib/python2.7/site-packages/django/contrib/gis/db/backends/postgis/operations.py", line 425, in postgis_lib_version
    return self._get_postgis_func('postgis_lib_version')
  File "/home/mpatlas/virtualenvs/mpatlas_dev/lib/python2.7/site-packages/django/contrib/gis/db/backends/postgis/operations.py", line 406, in _get_postgis_func
    cursor = self.connection._cursor()
  File "/home/mpatlas/virtualenvs/mpatlas_dev/lib/python2.7/site-packages/django/db/backends/postgresql_psycopg2/base.py", line 140, in _cursor
    self.connection = Database.connect(**conn_params)
  File "/home/mpatlas/projects/django_testgeo/testgeo/deploy/psyco_gevent.py", line 44, in gevent_wait_callback
    state = conn.poll()
OperationalError: asynchronous connection failed
2011-10-31 16:11:27 [12352] [INFO] Worker exiting (pid: 12352)
2011-10-31 23:11:27 [12345] [INFO] Shutting down: Master
2011-10-31 23:11:27 [12345] [INFO] Reason: Worker failed to boot.
2011-10-31 23:11:28 [12400] [INFO] Starting gunicorn 0.13.4
2011-10-31 23:11:28 [12400] [INFO] Listening at: unix:/home/mpatlas/projects/django_testgeo/testgeo/deploy/gunicorn.sock (12400)
2011-10-31 23:11:28 [12400] [INFO] Using worker: gevent
2011-10-31 23:11:28 [12407] [INFO] Booting worker with pid: 12407
2011-10-31 23:11:28 [12408] [INFO] Booting worker with pid: 12408
2011-10-31 23:11:28 [12407] [INFO] Made Psycopg Green
2011-10-31 23:11:28 [12408] [INFO] Made Psycopg Green
2011-10-31 16:11:29 [12408] [ERROR] Exception in worker process:
Traceback (most recent call last):
  File "/home/mpatlas/virtualenvs/mpatlas_dev/lib/python2.7/site-packages/gunicorn/arbiter.py", line 456, in spawn_worker
    worker.init_process()
  File "/home/mpatlas/virtualenvs/mpatlas_dev/lib/python2.7/site-packages/gunicorn/workers/ggevent.py", line 99, in init_process
    super(GeventWorker, self).init_process()
  File "/home/mpatlas/virtualenvs/mpatlas_dev/lib/python2.7/site-packages/gunicorn/workers/base.py", line 100, in init_process
    self.wsgi = self.app.wsgi()
  File "/home/mpatlas/virtualenvs/mpatlas_dev/lib/python2.7/site-packages/gunicorn/app/base.py", line 101, in wsgi
    self.callable = self.load()
  File "/home/mpatlas/virtualenvs/mpatlas_dev/lib/python2.7/site-packages/gunicorn/app/djangoapp.py", line 128, in load
    self.validate()
  File "/home/mpatlas/virtualenvs/mpatlas_dev/lib/python2.7/site-packages/gunicorn/app/djangoapp.py", line 116, in validate
    if get_validation_errors(s):
  File "/home/mpatlas/virtualenvs/mpatlas_dev/lib/python2.7/site-packages/django/core/management/validation.py", line 28, in get_validation_errors
    from django.db import models, connection
  File "/home/mpatlas/virtualenvs/mpatlas_dev/lib/python2.7/site-packages/django/db/__init__.py", line 78, in <module>
    connection = connections[DEFAULT_DB_ALIAS]
  File "/home/mpatlas/virtualenvs/mpatlas_dev/lib/python2.7/site-packages/django/db/utils.py", line 94, in __getitem__
    conn = backend.DatabaseWrapper(db, alias)
  File "/home/mpatlas/virtualenvs/mpatlas_dev/lib/python2.7/site-packages/django/contrib/gis/db/backends/postgis/base.py", line 11, in __init__
    self.ops = PostGISOperations(self)
  File "/home/mpatlas/virtualenvs/mpatlas_dev/lib/python2.7/site-packages/django/contrib/gis/db/backends/postgis/operations.py", line 91, in __init__
    vtup = self.postgis_version_tuple()
  File "/home/mpatlas/virtualenvs/mpatlas_dev/lib/python2.7/site-packages/django/contrib/gis/db/backends/postgis/operations.py", line 445, in postgis_version_tuple
    version = self.postgis_lib_version()
  File "/home/mpatlas/virtualenvs/mpatlas_dev/lib/python2.7/site-packages/django/contrib/gis/db/backends/postgis/operations.py", line 425, in postgis_lib_version
    return self._get_postgis_func('postgis_lib_version')
  File "/home/mpatlas/virtualenvs/mpatlas_dev/lib/python2.7/site-packages/django/contrib/gis/db/backends/postgis/operations.py", line 406, in _get_postgis_func
    cursor = self.connection._cursor()
  File "/home/mpatlas/virtualenvs/mpatlas_dev/lib/python2.7/site-packages/django/db/backends/postgresql_psycopg2/base.py", line 140, in _cursor
    self.connection = Database.connect(**conn_params)
  File "/home/mpatlas/projects/django_testgeo/testgeo/deploy/psyco_gevent.py", line 44, in gevent_wait_callback
    state = conn.poll()
OperationalError: asynchronous connection failed
2011-10-31 16:11:29 [12408] [INFO] Worker exiting (pid: 12408)
2011-10-31 16:11:29 [12407] [ERROR] Exception in worker process:
Traceback (most recent call last):
  File "/home/mpatlas/virtualenvs/mpatlas_dev/lib/python2.7/site-packages/gunicorn/arbiter.py", line 456, in spawn_worker
    worker.init_process()
  File "/home/mpatlas/virtualenvs/mpatlas_dev/lib/python2.7/site-packages/gunicorn/workers/ggevent.py", line 99, in init_process
    super(GeventWorker, self).init_process()
  File "/home/mpatlas/virtualenvs/mpatlas_dev/lib/python2.7/site-packages/gunicorn/workers/base.py", line 100, in init_process
    self.wsgi = self.app.wsgi()
  File "/home/mpatlas/virtualenvs/mpatlas_dev/lib/python2.7/site-packages/gunicorn/app/base.py", line 101, in wsgi
    self.callable = self.load()
  File "/home/mpatlas/virtualenvs/mpatlas_dev/lib/python2.7/site-packages/gunicorn/app/djangoapp.py", line 128, in load
    self.validate()
  File "/home/mpatlas/virtualenvs/mpatlas_dev/lib/python2.7/site-packages/gunicorn/app/djangoapp.py", line 116, in validate
    if get_validation_errors(s):
  File "/home/mpatlas/virtualenvs/mpatlas_dev/lib/python2.7/site-packages/django/core/management/validation.py", line 28, in get_validation_errors
    from django.db import models, connection
  File "/home/mpatlas/virtualenvs/mpatlas_dev/lib/python2.7/site-packages/django/db/__init__.py", line 78, in <module>
    connection = connections[DEFAULT_DB_ALIAS]
  File "/home/mpatlas/virtualenvs/mpatlas_dev/lib/python2.7/site-packages/django/db/utils.py", line 94, in __getitem__
    conn = backend.DatabaseWrapper(db, alias)
  File "/home/mpatlas/virtualenvs/mpatlas_dev/lib/python2.7/site-packages/django/contrib/gis/db/backends/postgis/base.py", line 11, in __init__
    self.ops = PostGISOperations(self)
  File "/home/mpatlas/virtualenvs/mpatlas_dev/lib/python2.7/site-packages/django/contrib/gis/db/backends/postgis/operations.py", line 91, in __init__
    vtup = self.postgis_version_tuple()
  File "/home/mpatlas/virtualenvs/mpatlas_dev/lib/python2.7/site-packages/django/contrib/gis/db/backends/postgis/operations.py", line 445, in postgis_version_tuple
    version = self.postgis_lib_version()
  File "/home/mpatlas/virtualenvs/mpatlas_dev/lib/python2.7/site-packages/django/contrib/gis/db/backends/postgis/operations.py", line 425, in postgis_lib_version
    return self._get_postgis_func('postgis_lib_version')
  File "/home/mpatlas/virtualenvs/mpatlas_dev/lib/python2.7/site-packages/django/contrib/gis/db/backends/postgis/operations.py", line 406, in _get_postgis_func
    cursor = self.connection._cursor()
  File "/home/mpatlas/virtualenvs/mpatlas_dev/lib/python2.7/site-packages/django/db/backends/postgresql_psycopg2/base.py", line 140, in _cursor
    self.connection = Database.connect(**conn_params)
  File "/home/mpatlas/projects/django_testgeo/testgeo/deploy/psyco_gevent.py", line 44, in gevent_wait_callback
    state = conn.poll()
OperationalError: asynchronous connection failed
2011-10-31 16:11:29 [12407] [INFO] Worker exiting (pid: 12407)
2011-10-31 23:11:30 [12400] [INFO] Shutting down: Master
2011-10-31 23:11:30 [12400] [INFO] Reason: Worker failed to boot.
2011-10-31 23:11:31 [12455] [INFO] Starting gunicorn 0.13.4
2011-10-31 23:11:31 [12455] [INFO] Listening at: unix:/home/mpatlas/projects/django_testgeo/testgeo/deploy/gunicorn.sock (12455)
2011-10-31 23:11:31 [12455] [INFO] Using worker: gevent
2011-10-31 23:11:31 [12462] [INFO] Booting worker with pid: 12462
2011-10-31 23:11:31 [12463] [INFO] Booting worker with pid: 12463
2011-10-31 23:11:31 [12462] [INFO] Made Psycopg Green
2011-10-31 23:11:31 [12463] [INFO] Made Psycopg Green
2011-10-31 16:11:31 [12462] [ERROR] Exception in worker process:
Traceback (most recent call last):
  File "/home/mpatlas/virtualenvs/mpatlas_dev/lib/python2.7/site-packages/gunicorn/arbiter.py", line 456, in spawn_worker
    worker.init_process()
  File "/home/mpatlas/virtualenvs/mpatlas_dev/lib/python2.7/site-packages/gunicorn/workers/ggevent.py", line 99, in init_process
    super(GeventWorker, self).init_process()
  File "/home/mpatlas/virtualenvs/mpatlas_dev/lib/python2.7/site-packages/gunicorn/workers/base.py", line 100, in init_process
    self.wsgi = self.app.wsgi()
  File "/home/mpatlas/virtualenvs/mpatlas_dev/lib/python2.7/site-packages/gunicorn/app/base.py", line 101, in wsgi
    self.callable = self.load()
  File "/home/mpatlas/virtualenvs/mpatlas_dev/lib/python2.7/site-packages/gunicorn/app/djangoapp.py", line 128, in load
    self.validate()
  File "/home/mpatlas/virtualenvs/mpatlas_dev/lib/python2.7/site-packages/gunicorn/app/djangoapp.py", line 116, in validate
    if get_validation_errors(s):
  File "/home/mpatlas/virtualenvs/mpatlas_dev/lib/python2.7/site-packages/django/core/management/validation.py", line 28, in get_validation_errors
    from django.db import models, connection
  File "/home/mpatlas/virtualenvs/mpatlas_dev/lib/python2.7/site-packages/django/db/__init__.py", line 78, in <module>
    connection = connections[DEFAULT_DB_ALIAS]
  File "/home/mpatlas/virtualenvs/mpatlas_dev/lib/python2.7/site-packages/django/db/utils.py", line 94, in __getitem__
    conn = backend.DatabaseWrapper(db, alias)
  File "/home/mpatlas/virtualenvs/mpatlas_dev/lib/python2.7/site-packages/django/contrib/gis/db/backends/postgis/base.py", line 11, in __init__
    self.ops = PostGISOperations(self)
  File "/home/mpatlas/virtualenvs/mpatlas_dev/lib/python2.7/site-packages/django/contrib/gis/db/backends/postgis/operations.py", line 91, in __init__
    vtup = self.postgis_version_tuple()
  File "/home/mpatlas/virtualenvs/mpatlas_dev/lib/python2.7/site-packages/django/contrib/gis/db/backends/postgis/operations.py", line 445, in postgis_version_tuple
    version = self.postgis_lib_version()
  File "/home/mpatlas/virtualenvs/mpatlas_dev/lib/python2.7/site-packages/django/contrib/gis/db/backends/postgis/operations.py", line 425, in postgis_lib_version
    return self._get_postgis_func('postgis_lib_version')
  File "/home/mpatlas/virtualenvs/mpatlas_dev/lib/python2.7/site-packages/django/contrib/gis/db/backends/postgis/operations.py", line 406, in _get_postgis_func
    cursor = self.connection._cursor()
  File "/home/mpatlas/virtualenvs/mpatlas_dev/lib/python2.7/site-packages/django/db/backends/postgresql_psycopg2/base.py", line 140, in _cursor
    self.connection = Database.connect(**conn_params)
  File "/home/mpatlas/projects/django_testgeo/testgeo/deploy/psyco_gevent.py", line 44, in gevent_wait_callback
    state = conn.poll()
OperationalError: asynchronous connection failed
2011-10-31 16:11:31 [12462] [INFO] Worker exiting (pid: 12462)
2011-10-31 16:11:31 [12463] [ERROR] Exception in worker process:
Traceback (most recent call last):
  File "/home/mpatlas/virtualenvs/mpatlas_dev/lib/python2.7/site-packages/gunicorn/arbiter.py", line 456, in spawn_worker
    worker.init_process()
  File "/home/mpatlas/virtualenvs/mpatlas_dev/lib/python2.7/site-packages/gunicorn/workers/ggevent.py", line 99, in init_process
    super(GeventWorker, self).init_process()
  File "/home/mpatlas/virtualenvs/mpatlas_dev/lib/python2.7/site-packages/gunicorn/workers/base.py", line 100, in init_process
    self.wsgi = self.app.wsgi()
  File "/home/mpatlas/virtualenvs/mpatlas_dev/lib/python2.7/site-packages/gunicorn/app/base.py", line 101, in wsgi
    self.callable = self.load()
  File "/home/mpatlas/virtualenvs/mpatlas_dev/lib/python2.7/site-packages/gunicorn/app/djangoapp.py", line 128, in load
    self.validate()
  File "/home/mpatlas/virtualenvs/mpatlas_dev/lib/python2.7/site-packages/gunicorn/app/djangoapp.py", line 116, in validate
    if get_validation_errors(s):
  File "/home/mpatlas/virtualenvs/mpatlas_dev/lib/python2.7/site-packages/django/core/management/validation.py", line 28, in get_validation_errors
    from django.db import models, connection
  File "/home/mpatlas/virtualenvs/mpatlas_dev/lib/python2.7/site-packages/django/db/__init__.py", line 78, in <module>
    connection = connections[DEFAULT_DB_ALIAS]
  File "/home/mpatlas/virtualenvs/mpatlas_dev/lib/python2.7/site-packages/django/db/utils.py", line 94, in __getitem__
    conn = backend.DatabaseWrapper(db, alias)
  File "/home/mpatlas/virtualenvs/mpatlas_dev/lib/python2.7/site-packages/django/contrib/gis/db/backends/postgis/base.py", line 11, in __init__
    self.ops = PostGISOperations(self)
  File "/home/mpatlas/virtualenvs/mpatlas_dev/lib/python2.7/site-packages/django/contrib/gis/db/backends/postgis/operations.py", line 91, in __init__
    vtup = self.postgis_version_tuple()
  File "/home/mpatlas/virtualenvs/mpatlas_dev/lib/python2.7/site-packages/django/contrib/gis/db/backends/postgis/operations.py", line 445, in postgis_version_tuple
    version = self.postgis_lib_version()
  File "/home/mpatlas/virtualenvs/mpatlas_dev/lib/python2.7/site-packages/django/contrib/gis/db/backends/postgis/operations.py", line 425, in postgis_lib_version
    return self._get_postgis_func('postgis_lib_version')
  File "/home/mpatlas/virtualenvs/mpatlas_dev/lib/python2.7/site-packages/django/contrib/gis/db/backends/postgis/operations.py", line 406, in _get_postgis_func
    cursor = self.connection._cursor()
  File "/home/mpatlas/virtualenvs/mpatlas_dev/lib/python2.7/site-packages/django/db/backends/postgresql_psycopg2/base.py", line 140, in _cursor
    self.connection = Database.connect(**conn_params)
  File "/home/mpatlas/projects/django_testgeo/testgeo/deploy/psyco_gevent.py", line 44, in gevent_wait_callback
    state = conn.poll()
OperationalError: asynchronous connection failed
2011-10-31 16:11:31 [12463] [INFO] Worker exiting (pid: 12463)
2011-10-31 23:11:32 [12455] [INFO] Shutting down: Master
2011-10-31 23:11:32 [12455] [INFO] Reason: Worker failed to boot.
2011-10-31 23:11:33 [12511] [INFO] Starting gunicorn 0.13.4
2011-10-31 23:11:33 [12511] [INFO] Listening at: unix:/home/mpatlas/projects/django_testgeo/testgeo/deploy/gunicorn.sock (12511)
2011-10-31 23:11:33 [12511] [INFO] Using worker: gevent
2011-10-31 23:11:33 [12518] [INFO] Booting worker with pid: 12518
2011-10-31 23:11:33 [12519] [INFO] Booting worker with pid: 12519
2011-10-31 23:11:33 [12519] [INFO] Made Psycopg Green
2011-10-31 23:11:33 [12518] [INFO] Made Psycopg Green
2011-10-31 16:11:34 [12519] [ERROR] Exception in worker process:
Traceback (most recent call last):
  File "/home/mpatlas/virtualenvs/mpatlas_dev/lib/python2.7/site-packages/gunicorn/arbiter.py", line 456, in spawn_worker
    worker.init_process()
  File "/home/mpatlas/virtualenvs/mpatlas_dev/lib/python2.7/site-packages/gunicorn/workers/ggevent.py", line 99, in init_process
    super(GeventWorker, self).init_process()
  File "/home/mpatlas/virtualenvs/mpatlas_dev/lib/python2.7/site-packages/gunicorn/workers/base.py", line 100, in init_process
    self.wsgi = self.app.wsgi()
  File "/home/mpatlas/virtualenvs/mpatlas_dev/lib/python2.7/site-packages/gunicorn/app/base.py", line 101, in wsgi
    self.callable = self.load()
  File "/home/mpatlas/virtualenvs/mpatlas_dev/lib/python2.7/site-packages/gunicorn/app/djangoapp.py", line 128, in load
    self.validate()
  File "/home/mpatlas/virtualenvs/mpatlas_dev/lib/python2.7/site-packages/gunicorn/app/djangoapp.py", line 116, in validate
    if get_validation_errors(s):
  File "/home/mpatlas/virtualenvs/mpatlas_dev/lib/python2.7/site-packages/django/core/management/validation.py", line 28, in get_validation_errors
    from django.db import models, connection
  File "/home/mpatlas/virtualenvs/mpatlas_dev/lib/python2.7/site-packages/django/db/__init__.py", line 78, in <module>
    connection = connections[DEFAULT_DB_ALIAS]
  File "/home/mpatlas/virtualenvs/mpatlas_dev/lib/python2.7/site-packages/django/db/utils.py", line 94, in __getitem__
    conn = backend.DatabaseWrapper(db, alias)
  File "/home/mpatlas/virtualenvs/mpatlas_dev/lib/python2.7/site-packages/django/contrib/gis/db/backends/postgis/base.py", line 11, in __init__
    self.ops = PostGISOperations(self)
  File "/home/mpatlas/virtualenvs/mpatlas_dev/lib/python2.7/site-packages/django/contrib/gis/db/backends/postgis/operations.py", line 91, in __init__
    vtup = self.postgis_version_tuple()
  File "/home/mpatlas/virtualenvs/mpatlas_dev/lib/python2.7/site-packages/django/contrib/gis/db/backends/postgis/operations.py", line 445, in postgis_version_tuple
    version = self.postgis_lib_version()
  File "/home/mpatlas/virtualenvs/mpatlas_dev/lib/python2.7/site-packages/django/contrib/gis/db/backends/postgis/operations.py", line 425, in postgis_lib_version
    return self._get_postgis_func('postgis_lib_version')
  File "/home/mpatlas/virtualenvs/mpatlas_dev/lib/python2.7/site-packages/django/contrib/gis/db/backends/postgis/operations.py", line 406, in _get_postgis_func
    cursor = self.connection._cursor()
  File "/home/mpatlas/virtualenvs/mpatlas_dev/lib/python2.7/site-packages/django/db/backends/postgresql_psycopg2/base.py", line 140, in _cursor
    self.connection = Database.connect(**conn_params)
  File "/home/mpatlas/projects/django_testgeo/testgeo/deploy/psyco_gevent.py", line 44, in gevent_wait_callback
    state = conn.poll()
OperationalError: asynchronous connection failed
2011-10-31 16:11:34 [12519] [INFO] Worker exiting (pid: 12519)
2011-10-31 16:11:34 [12518] [ERROR] Exception in worker process:
Traceback (most recent call last):
  File "/home/mpatlas/virtualenvs/mpatlas_dev/lib/python2.7/site-packages/gunicorn/arbiter.py", line 456, in spawn_worker
    worker.init_process()
  File "/home/mpatlas/virtualenvs/mpatlas_dev/lib/python2.7/site-packages/gunicorn/workers/ggevent.py", line 99, in init_process
    super(GeventWorker, self).init_process()
  File "/home/mpatlas/virtualenvs/mpatlas_dev/lib/python2.7/site-packages/gunicorn/workers/base.py", line 100, in init_process
    self.wsgi = self.app.wsgi()
  File "/home/mpatlas/virtualenvs/mpatlas_dev/lib/python2.7/site-packages/gunicorn/app/base.py", line 101, in wsgi
    self.callable = self.load()
  File "/home/mpatlas/virtualenvs/mpatlas_dev/lib/python2.7/site-packages/gunicorn/app/djangoapp.py", line 128, in load
    self.validate()
  File "/home/mpatlas/virtualenvs/mpatlas_dev/lib/python2.7/site-packages/gunicorn/app/djangoapp.py", line 116, in validate
    if get_validation_errors(s):
  File "/home/mpatlas/virtualenvs/mpatlas_dev/lib/python2.7/site-packages/django/core/management/validation.py", line 28, in get_validation_errors
    from django.db import models, connection
  File "/home/mpatlas/virtualenvs/mpatlas_dev/lib/python2.7/site-packages/django/db/__init__.py", line 78, in <module>
    connection = connections[DEFAULT_DB_ALIAS]
  File "/home/mpatlas/virtualenvs/mpatlas_dev/lib/python2.7/site-packages/django/db/utils.py", line 94, in __getitem__
    conn = backend.DatabaseWrapper(db, alias)
  File "/home/mpatlas/virtualenvs/mpatlas_dev/lib/python2.7/site-packages/django/contrib/gis/db/backends/postgis/base.py", line 11, in __init__
    self.ops = PostGISOperations(self)
  File "/home/mpatlas/virtualenvs/mpatlas_dev/lib/python2.7/site-packages/django/contrib/gis/db/backends/postgis/operations.py", line 91, in __init__
    vtup = self.postgis_version_tuple()
  File "/home/mpatlas/virtualenvs/mpatlas_dev/lib/python2.7/site-packages/django/contrib/gis/db/backends/postgis/operations.py", line 445, in postgis_version_tuple
    version = self.postgis_lib_version()
  File "/home/mpatlas/virtualenvs/mpatlas_dev/lib/python2.7/site-packages/django/contrib/gis/db/backends/postgis/operations.py", line 425, in postgis_lib_version
    return self._get_postgis_func('postgis_lib_version')
  File "/home/mpatlas/virtualenvs/mpatlas_dev/lib/python2.7/site-packages/django/contrib/gis/db/backends/postgis/operations.py", line 406, in _get_postgis_func
    cursor = self.connection._cursor()
  File "/home/mpatlas/virtualenvs/mpatlas_dev/lib/python2.7/site-packages/django/db/backends/postgresql_psycopg2/base.py", line 140, in _cursor
    self.connection = Database.connect(**conn_params)
  File "/home/mpatlas/projects/django_testgeo/testgeo/deploy/psyco_gevent.py", line 44, in gevent_wait_callback
    state = conn.poll()
OperationalError: asynchronous connection failed
2011-10-31 16:11:34 [12518] [INFO] Worker exiting (pid: 12518)
2011-10-31 23:11:34 [12511] [INFO] Shutting down: Master
2011-10-31 23:11:34 [12511] [INFO] Reason: Worker failed to boot.
2011-10-31 23:11:36 [12566] [INFO] Starting gunicorn 0.13.4
2011-10-31 23:11:36 [12566] [INFO] Listening at: unix:/home/mpatlas/projects/django_testgeo/testgeo/deploy/gunicorn.sock (12566)
2011-10-31 23:11:36 [12566] [INFO] Using worker: gevent
2011-10-31 23:11:36 [12573] [INFO] Booting worker with pid: 12573
2011-10-31 23:11:36 [12574] [INFO] Booting worker with pid: 12574
2011-10-31 23:11:36 [12574] [INFO] Made Psycopg Green
2011-10-31 23:11:36 [12573] [INFO] Made Psycopg Green
2011-10-31 16:11:37 [12574] [ERROR] Exception in worker process:
Traceback (most recent call last):
  File "/home/mpatlas/virtualenvs/mpatlas_dev/lib/python2.7/site-packages/gunicorn/arbiter.py", line 456, in spawn_worker
    worker.init_process()
  File "/home/mpatlas/virtualenvs/mpatlas_dev/lib/python2.7/site-packages/gunicorn/workers/ggevent.py", line 99, in init_process
    super(GeventWorker, self).init_process()
  File "/home/mpatlas/virtualenvs/mpatlas_dev/lib/python2.7/site-packages/gunicorn/workers/base.py", line 100, in init_process
    self.wsgi = self.app.wsgi()
  File "/home/mpatlas/virtualenvs/mpatlas_dev/lib/python2.7/site-packages/gunicorn/app/base.py", line 101, in wsgi
    self.callable = self.load()
  File "/home/mpatlas/virtualenvs/mpatlas_dev/lib/python2.7/site-packages/gunicorn/app/djangoapp.py", line 128, in load
    self.validate()
  File "/home/mpatlas/virtualenvs/mpatlas_dev/lib/python2.7/site-packages/gunicorn/app/djangoapp.py", line 116, in validate
    if get_validation_errors(s):
  File "/home/mpatlas/virtualenvs/mpatlas_dev/lib/python2.7/site-packages/django/core/management/validation.py", line 28, in get_validation_errors
    from django.db import models, connection
  File "/home/mpatlas/virtualenvs/mpatlas_dev/lib/python2.7/site-packages/django/db/__init__.py", line 78, in <module>
    connection = connections[DEFAULT_DB_ALIAS]
  File "/home/mpatlas/virtualenvs/mpatlas_dev/lib/python2.7/site-packages/django/db/utils.py", line 94, in __getitem__
    conn = backend.DatabaseWrapper(db, alias)
  File "/home/mpatlas/virtualenvs/mpatlas_dev/lib/python2.7/site-packages/django/contrib/gis/db/backends/postgis/base.py", line 11, in __init__
    self.ops = PostGISOperations(self)
  File "/home/mpatlas/virtualenvs/mpatlas_dev/lib/python2.7/site-packages/django/contrib/gis/db/backends/postgis/operations.py", line 91, in __init__
    vtup = self.postgis_version_tuple()
  File "/home/mpatlas/virtualenvs/mpatlas_dev/lib/python2.7/site-packages/django/contrib/gis/db/backends/postgis/operations.py", line 445, in postgis_version_tuple
    version = self.postgis_lib_version()
  File "/home/mpatlas/virtualenvs/mpatlas_dev/lib/python2.7/site-packages/django/contrib/gis/db/backends/postgis/operations.py", line 425, in postgis_lib_version
    return self._get_postgis_func('postgis_lib_version')
  File "/home/mpatlas/virtualenvs/mpatlas_dev/lib/python2.7/site-packages/django/contrib/gis/db/backends/postgis/operations.py", line 406, in _get_postgis_func
    cursor = self.connection._cursor()
  File "/home/mpatlas/virtualenvs/mpatlas_dev/lib/python2.7/site-packages/django/db/backends/postgresql_psycopg2/base.py", line 140, in _cursor
    self.connection = Database.connect(**conn_params)
  File "/home/mpatlas/projects/django_testgeo/testgeo/deploy/psyco_gevent.py", line 44, in gevent_wait_callback
    state = conn.poll()
OperationalError: asynchronous connection failed
2011-10-31 16:11:37 [12574] [INFO] Worker exiting (pid: 12574)
2011-10-31 16:11:37 [12573] [ERROR] Exception in worker process:
Traceback (most recent call last):
  File "/home/mpatlas/virtualenvs/mpatlas_dev/lib/python2.7/site-packages/gunicorn/arbiter.py", line 456, in spawn_worker
    worker.init_process()
  File "/home/mpatlas/virtualenvs/mpatlas_dev/lib/python2.7/site-packages/gunicorn/workers/ggevent.py", line 99, in init_process
    super(GeventWorker, self).init_process()
  File "/home/mpatlas/virtualenvs/mpatlas_dev/lib/python2.7/site-packages/gunicorn/workers/base.py", line 100, in init_process
    self.wsgi = self.app.wsgi()
  File "/home/mpatlas/virtualenvs/mpatlas_dev/lib/python2.7/site-packages/gunicorn/app/base.py", line 101, in wsgi
    self.callable = self.load()
  File "/home/mpatlas/virtualenvs/mpatlas_dev/lib/python2.7/site-packages/gunicorn/app/djangoapp.py", line 128, in load
    self.validate()
  File "/home/mpatlas/virtualenvs/mpatlas_dev/lib/python2.7/site-packages/gunicorn/app/djangoapp.py", line 116, in validate
    if get_validation_errors(s):
  File "/home/mpatlas/virtualenvs/mpatlas_dev/lib/python2.7/site-packages/django/core/management/validation.py", line 28, in get_validation_errors
    from django.db import models, connection
  File "/home/mpatlas/virtualenvs/mpatlas_dev/lib/python2.7/site-packages/django/db/__init__.py", line 78, in <module>
    connection = connections[DEFAULT_DB_ALIAS]
  File "/home/mpatlas/virtualenvs/mpatlas_dev/lib/python2.7/site-packages/django/db/utils.py", line 94, in __getitem__
    conn = backend.DatabaseWrapper(db, alias)
  File "/home/mpatlas/virtualenvs/mpatlas_dev/lib/python2.7/site-packages/django/contrib/gis/db/backends/postgis/base.py", line 11, in __init__
    self.ops = PostGISOperations(self)
  File "/home/mpatlas/virtualenvs/mpatlas_dev/lib/python2.7/site-packages/django/contrib/gis/db/backends/postgis/operations.py", line 91, in __init__
    vtup = self.postgis_version_tuple()
  File "/home/mpatlas/virtualenvs/mpatlas_dev/lib/python2.7/site-packages/django/contrib/gis/db/backends/postgis/operations.py", line 445, in postgis_version_tuple
    version = self.postgis_lib_version()
  File "/home/mpatlas/virtualenvs/mpatlas_dev/lib/python2.7/site-packages/django/contrib/gis/db/backends/postgis/operations.py", line 425, in postgis_lib_version
    return self._get_postgis_func('postgis_lib_version')
  File "/home/mpatlas/virtualenvs/mpatlas_dev/lib/python2.7/site-packages/django/contrib/gis/db/backends/postgis/operations.py", line 406, in _get_postgis_func
    cursor = self.connection._cursor()
  File "/home/mpatlas/virtualenvs/mpatlas_dev/lib/python2.7/site-packages/django/db/backends/postgresql_psycopg2/base.py", line 140, in _cursor
    self.connection = Database.connect(**conn_params)
  File "/home/mpatlas/projects/django_testgeo/testgeo/deploy/psyco_gevent.py", line 44, in gevent_wait_callback
    state = conn.poll()
OperationalError: asynchronous connection failed
2011-10-31 16:11:37 [12573] [INFO] Worker exiting (pid: 12573)
2011-10-31 23:11:37 [12566] [INFO] Shutting down: Master
2011-10-31 23:11:37 [12566] [INFO] Reason: Worker failed to boot.
2011-10-31 23:18:40 [12954] [INFO] Starting gunicorn 0.13.4
2011-10-31 23:18:40 [12954] [INFO] Listening at: unix:/home/mpatlas/projects/django_testgeo/testgeo/deploy/gunicorn.sock (12954)
2011-10-31 23:18:40 [12954] [INFO] Using worker: gevent
2011-10-31 23:18:40 [12961] [INFO] Booting worker with pid: 12961
2011-10-31 23:18:40 [12962] [INFO] Booting worker with pid: 12962
2011-10-31 23:18:40 [12961] [INFO] Made Psycopg Green
2011-10-31 23:18:40 [12962] [INFO] Made Psycopg Green
